<?xml version="1.0"?>
<robot name="mechelangelo">

  <!-- =========================
       BASE LINK
       ========================= -->
  <link name="base_link">
    <visual>
      <origin xyz="0 0 0" rpy="0 0 0"/>
      <geometry>
        <mesh filename="package://mechelangelo_description/meshes/base/base.dae" scale=" 1 1 1"/>
      </geometry>
    </visual>

    <collision>
      <origin xyz="0 0 0.10" rpy="0 0 0"/>
      <geometry>
        <mesh filename="package://mechelangelo_description/meshes/base/base.dae" scale=" 1 1 1"/>
      </geometry>
    </collision>

    <inertial>
      <origin xyz="0 0 0.10" rpy="0 0 0"/>
      <mass value="12.0"/>
      <inertia
        ixx="0.30"
        ixy="0.0"
        ixz="0.0"
        iyy="0.40"
        iyz="0.0"
        izz="0.50"/>
    </inertial>
  </link>

  <!-- =========================
       LEFT WHEEL LINK
       ========================= -->
  <link name="left_wheel_link">
    <visual>
      <origin xyz="0.11091 0.20103 0.075" rpy="0 0 0"/>
      <geometry>
        <mesh filename="package://mechelangelo_description/meshes/wheels/wheel.dae" scale="1 1 1"/>
      </geometry>
    </visual>

    <collision>
      <origin xyz="0 0 0" rpy="0 0 0"/>
      <geometry>
        <cylinder radius="0.075" length="0.03"/>
      </geometry>
    </collision>

    <inertial>
      <origin xyz="0 0 0" rpy="0 0 0"/>
      <mass value="1.0"/>
      <inertia
        ixx="0.002"
        ixy="0.0"
        ixz="0.0"
        iyy="0.001"
        iyz="0.0"
        izz="0.002"/>
    </inertial>
  </link>

  <!-- =========================
       RIGHT WHEEL LINK
       ========================= -->
  <link name="right_wheel_link">
    <visual>
      <origin xyz="0.11091 -0.20103 0.075" rpy="0 0 0"/>
      <geometry>
        <mesh filename="package://mechelangelo_description/meshes/wheels/wheel.dae" scale="1 1 1"/>
      </geometry>
    </visual>

    <collision>
      <origin xyz="0 0 0" rpy="0 0 0"/>
      <geometry>
        <cylinder radius="0.075" length="0.03"/>
      </geometry>
    </collision>

    <inertial>
      <origin xyz="0 0 0" rpy="0 0 0"/>
      <mass value="1.0"/>
      <inertia
        ixx="0.002"
        ixy="0.0"
        ixz="0.0"
        iyy="0.001"
        iyz="0.0"
        izz="0.002"/>
    </inertial>
  </link>

  <!-- =========================
       WHEEL JOINTS
       ========================= -->
  <joint name="left_wheel_joint" type="continuous">
    <parent link="base_link"/>
    <child link="left_wheel_link"/>
    <origin xyz="0 0 0" rpy="0 0 0"/>
    <axis xyz="0 1 0"/>
  </joint>

  <joint name="right_wheel_joint" type="continuous">
    <parent link="base_link"/>
    <child link="right_wheel_link"/>
    <origin xyz="0 0 0" rpy="0 0 0"/>
    <axis xyz="0 1 0"/>
  </joint>

  <!-- =========================
       REAR CASTER SUPPORT
       Needed so robot is stable in Gazebo
       ========================= -->
  <link name="caster_link">
    <visual>
      <origin xyz="0 0 0" rpy="0 0 0"/>
      <geometry>
        <sphere radius="0.03"/>
      </geometry>
    </visual>

    <collision>
      <origin xyz="0 0 0" rpy="0 0 0"/>
      <geometry>
        <sphere radius="0.03"/>
      </geometry>
    </collision>

    <inertial>
      <origin xyz="0 0 0" rpy="0 0 0"/>
      <mass value="0.2"/>
      <inertia
        ixx="0.0001"
        ixy="0.0"
        ixz="0.0"
        iyy="0.0001"
        iyz="0.0"
        izz="0.0001"/>
    </inertial>
  </link>

  <joint name="caster_joint" type="fixed">
    <parent link="base_link"/>
    <child link="caster_link"/>
    <origin xyz="-0.18 0.0 0.03" rpy="0 0 0"/>
  </joint>

  <!-- =========================
       LASER SCAN
       ========================= -->
  <joint name="scan_joint" type="fixed">
    <parent link="base_link"/>
    <child link="base_scan"/>
    <origin xyz="0 0 0.280" rpy="0 0 0"/>
  </joint>

  <link name="base_scan">
    <visual>
      <origin xyz="0 0 0" rpy="0 0 0"/>
      <geometry>
        <mesh filename="package://mechelangelo_description/meshes/sensors/lds.stl" scale="1 1 1"/>
      </geometry>
    </visual>

    <inertial>
      <origin xyz="0 0 0" rpy="0 0 0"/>
      <mass value="0.114"/>
      <inertia
        ixx="0.001"
        ixy="0.0"
        ixz="0.0"
        iyy="0.001"
        iyz="0.0"
        izz="0.001"/>
    </inertial>
  </link>

  <!-- =========================
       IMU
       ========================= -->
  <joint name="imu_joint" type="fixed">
    <parent link="base_link"/>
    <child link="imu_link"/>
    <origin xyz="0.0 0 0.068" rpy="0 0 0"/>
  </joint>

  <link name="imu_link">
    <inertial>
      <origin xyz="0 0 0" rpy="0 0 0"/>
      <mass value="0.01"/>
      <inertia
        ixx="0.00001"
        ixy="0.0"
        ixz="0.0"
        iyy="0.00001"
        iyz="0.0"
        izz="0.00001"/>
    </inertial>
  </link>

  <!-- =========================
       CAMERA
       ========================= -->
  <joint name="camera_joint" type="fixed">
    <origin xyz="0 0 1.480" rpy="0 0 0"/>
    <parent link="base_link"/>
    <child link="camera_link"/>
  </joint>

  <link name="camera_link">
    <visual>
      <origin xyz="0 0 0" rpy="0 0 0"/>
      <geometry>
        <box size="0.015 0.030 0.027"/>
      </geometry>
    </visual>

    <collision>
      <origin xyz="0 0 0" rpy="0 0 0"/>
      <geometry>
        <box size="0.015 0.030 0.027"/>
      </geometry>
    </collision>

    <inertial>
      <origin xyz="0 0 0" rpy="0 0 0"/>
      <mass value="0.05"/>
      <inertia
        ixx="0.00001"
        ixy="0.0"
        ixz="0.0"
        iyy="0.00001"
        iyz="0.0"
        izz="0.00001"/>
    </inertial>
  </link>

  <joint name="camera_rgb_joint" type="fixed">
    <origin xyz="0 0 0" rpy="0 0 0"/>
    <parent link="camera_link"/>
    <child link="camera_rgb_frame"/>
  </joint>
  <link name="camera_rgb_frame"/>

  <joint name="camera_rgb_optical_joint" type="fixed">
    <origin xyz="0 0 0" rpy="-1.5708 0 -1.5708"/>
    <parent link="camera_rgb_frame"/>
    <child link="camera_rgb_optical_frame"/>
  </joint>
  <link name="camera_rgb_optical_frame"/>

  <!-- =========================
       GAZEBO MATERIAL / CONTACT
       ========================= -->
  <gazebo reference="left_wheel_link">
    <mu1>1.0</mu1>
    <mu2>1.0</mu2>
    <kp>1000000.0</kp>
    <kd>100.0</kd>
  </gazebo>

  <gazebo reference="right_wheel_link">
    <mu1>1.0</mu1>
    <mu2>1.0</mu2>
    <kp>1000000.0</kp>
    <kd>100.0</kd>
  </gazebo>

  <gazebo reference="caster_link">
    <mu1>0.2</mu1>
    <mu2>0.2</mu2>
  </gazebo>

  <!-- =========================
       DIFF DRIVE PLUGIN
       ========================= -->
  <gazebo>
    <plugin name="gazebo_ros_diff_drive" filename="libgazebo_ros_diff_drive.so">
      <update_rate>50</update_rate>

      <left_joint>left_wheel_joint</left_joint>
      <right_joint>right_wheel_joint</right_joint>

      <wheel_separation>0.40206</wheel_separation>
      <wheel_diameter>0.15</wheel_diameter>

      <max_wheel_torque>20.0</max_wheel_torque>
      <max_wheel_acceleration>5.0</max_wheel_acceleration>

      <command_topic>cmd_vel</command_topic>
      <odometry_topic>odom</odometry_topic>
      <odometry_frame>odom</odometry_frame>
      <robot_base_frame>base_link</robot_base_frame>

      <publish_odom>true</publish_odom>
      <publish_odom_tf>true</publish_odom_tf>
      <publish_wheel_tf>false</publish_wheel_tf>
      <publishWheelJointState>true</publishWheelJointState>
    </plugin>
  </gazebo>

  <!-- =========================
       LIDAR SENSOR
       ========================= -->
  <gazebo reference="base_scan">
    <sensor name="lidar_sensor" type="ray">
      <always_on>true</always_on>
      <visualize>true</visualize>
      <update_rate>10</update_rate>

      <ray>
        <scan>
          <horizontal>
            <samples>720</samples>
            <resolution>1</resolution>
            <min_angle>-3.14159</min_angle>
            <max_angle>3.14159</max_angle>
          </horizontal>
        </scan>
        <range>
          <min>0.12</min>
          <max>8.0</max>
          <resolution>0.01</resolution>
        </range>
      </ray>

      <plugin name="gazebo_ros_ray_sensor" filename="libgazebo_ros_ray_sensor.so">
        <ros>
          <remapping>~/out:=scan</remapping>
        </ros>
        <output_type>sensor_msgs/LaserScan</output_type>
        <frame_name>base_scan</frame_name>
      </plugin>
    </sensor>
  </gazebo>

  <!-- =========================
       CAMERA SENSOR
         ========================= -->
       
  <gazebo reference="camera_link">
    <sensor name="camera_sensor" type="camera">
      <always_on>true</always_on>
      <visualize>true</visualize>
      <update_rate>15</update_rate>

      <camera>
        <horizontal_fov>1.3962634</horizontal_fov>
        <image>
          <width>640</width>
          <height>480</height>
          <format>R8G8B8</format>
        </image>
        <clip>
          <near>0.05</near>
          <far>20.0</far>
        </clip>
      </camera>

      <plugin name="gazebo_ros_camera" filename="libgazebo_ros_camera.so">
        <frame_name>camera_rgb_optical_frame</frame_name>
        <ros>
          <remapping>~/image_raw:=camera/image_raw</remapping>
          <remapping>~/camera_info:=camera/camera_info</remapping>
        </ros>
      </plugin>
    </sensor>
  </gazebo>

</robot>
